<robot name="Auto-Generated: 67f8671c0c4e418085f7d3e6d7e8170b">
	<link name="base_rev_joint.base_motor_link">
		<inertial>
			<origin xyz="0.0 0.0 0.0" rpy="3.141592653589793 0.0 3.141592653589793" />
			<mass value="0.0" />
			<inertia ixx="0.0" ixy="0.0" ixz="0.0" iyy="0.0" iyz="0.0" izz="0.0" />
		</inertial>
		<visual name="base_rev_joint.base_motor_link_visual">
			<origin xyz="0.0 0.0 0.0" rpy="3.141592653589793 0.0 3.141592653589793" />
			<geometry>
				<mesh filename="assets/Assem_4310_BASE/Assem_4310_BASE/meshes/base_motor_link.STL" scale="1.0 1.0 1.0" />
			</geometry>
		</visual>
		<collision name="base_rev_joint.base_motor_link_collision">
			<origin xyz="0.0 0.0 0.0" rpy="3.141592653589793 0.0 3.141592653589793" />
			<geometry>
				<mesh filename="assets/Assem_4310_BASE/Assem_4310_BASE/meshes/base_motor_link.STL" scale="1.0 1.0 1.0" />
			</geometry>
		</collision>
	</link>
	<link name="base_rev_joint.base_out_link">
		<inertial>
			<origin xyz="0.0 0.0 0.0" rpy="0.0 0.0 0.0" />
			<mass value="0.0" />
			<inertia ixx="0.0" ixy="0.0" ixz="0.0" iyy="0.0" iyz="0.0" izz="0.0" />
		</inertial>
		<visual name="base_rev_joint.base_out_link_visual">
			<origin xyz="0.0 0.0 0.0" rpy="0.0 0.0 0.0" />
			<geometry>
				<mesh filename="assets/Assem_4310_BASE/Assem_4310_BASE/meshes/base_out_link.STL" scale="1.0 1.0 1.0" />
			</geometry>
		</visual>
		<collision name="base_rev_joint.base_out_link_collision">
			<origin xyz="0.0 0.0 0.0" rpy="0.0 0.0 0.0" />
			<geometry>
				<mesh filename="assets/Assem_4310_BASE/Assem_4310_BASE/meshes/base_out_link.STL" scale="1.0 1.0 1.0" />
			</geometry>
		</collision>
	</link>
	<link name="baseto4310-0.15.baseto4310-0.15">
		<inertial>
			<origin xyz="0.0 0.0 -0.075" rpy="0.0 0.0 0.0" />
			<mass value="9.375000000000002e-05" />
			<inertia ixx="1.7822265625e-07" ixy="0.0" ixz="0.0" iyy="1.7822265625e-07" iyz="0.0" izz="4.882812500000001e-09" />
		</inertial>
		<visual name="baseto4310-0.15.baseto4310-0.15_visual">
			<origin xyz="0.0 0.0 -0.075" rpy="0.0 0.0 0.0" />
			<geometry>
				<box size="0.025 0.025 0.15" />
			</geometry>
		</visual>
		<collision name="baseto4310-0.15.baseto4310-0.15_collision">
			<origin xyz="0.0 0.0 -0.075" rpy="0.0 0.0 0.0" />
			<geometry>
				<box size="0.025 0.025 0.15" />
			</geometry>
		</collision>
	</link>
	<link name="motor4310_rev_joint.motor4310_in_link">
		<inertial>
			<origin xyz="0.0012212 -4.3571e-06 0.035478" rpy="0.0 0.0 0.0" />
			<mass value="0.57649" />
			<inertia ixx="0.00051876" ixy="-5.0519e-08" ixz="-5.0469e-06" iyy="0.00039258" iyz="3.4788e-08" izz="0.00029808" />
		</inertial>
		<visual name="motor4310_rev_joint.motor4310_in_link_visual">
			<origin xyz="0.0 0.0 0.0" rpy="0.0 0.0 0.0" />
			<geometry>
				<mesh filename="assets/Assem_4310_JOINT/Assem_4310_JOINT/meshes/motor4310_in_link.STL" scale="1.0 1.0 1.0" />
			</geometry>
		</visual>
		<collision name="motor4310_rev_joint.motor4310_in_link_collision">
			<origin xyz="0.0 0.0 0.0" rpy="0.0 0.0 0.0" />
			<geometry>
				<mesh filename="assets/Assem_4310_JOINT/Assem_4310_JOINT/meshes/motor4310_in_link.STL" scale="1.0 1.0 1.0" />
			</geometry>
		</collision>
	</link>
	<link name="motor4310_rev_joint.motor4310_out_link">
		<inertial>
			<origin xyz="-2.5332e-10 0.0011054 0.013691" rpy="-1.5707963267948966 0.0 0.0" />
			<mass value="0.088545" />
			<inertia ixx="2.4599e-05" ixy="-3.8934e-22" ixz="-1.8263e-21" iyy="3.0632e-05" iyz="7.8406e-07" izz="2.5766e-05" />
		</inertial>
		<visual name="motor4310_rev_joint.motor4310_out_link_visual">
			<origin xyz="0.0 0.0 0.0" rpy="-1.5707963267948966 0.0 0.0" />
			<geometry>
				<mesh filename="assets/Assem_4310_JOINT/Assem_4310_JOINT/meshes/motor4310_out_link.STL" scale="1.0 1.0 1.0" />
			</geometry>
		</visual>
		<collision name="motor4310_rev_joint.motor4310_out_link_collision">
			<origin xyz="0.0 0.0 0.0" rpy="-1.5707963267948966 0.0 0.0" />
			<geometry>
				<mesh filename="assets/Assem_4310_JOINT/Assem_4310_JOINT/meshes/motor4310_out_link.STL" scale="1.0 1.0 1.0" />
			</geometry>
		</collision>
	</link>
	<link name="r4310to4310-0.45.r4310to4310-0.45">
		<inertial>
			<origin xyz="0.0 0.025 0.2125" rpy="0.0 0.0 0.0" />
			<mass value="0.0002812500000000001" />
			<inertia ixx="4.753417968750002e-06" ixy="0.0" ixz="0.0" iyy="4.753417968750002e-06" iyz="0.0" izz="1.4648437500000007e-08" />
		</inertial>
		<visual name="r4310to4310-0.45.r4310to4310-0.45_visual">
			<origin xyz="0.0 0.025 0.2125" rpy="0.0 0.0 0.0" />
			<geometry>
				<box size="0.025 0.025 0.45" />
			</geometry>
		</visual>
		<collision name="r4310to4310-0.45.r4310to4310-0.45_collision">
			<origin xyz="0.0 0.025 0.2125" rpy="0.0 0.0 0.0" />
			<geometry>
				<box size="0.025 0.025 0.45" />
			</geometry>
		</collision>
	</link>
	<link name="motor4310_rev_joint-1.motor4310_in_link">
		<inertial>
			<origin xyz="0.0012212 -4.3571e-06 0.035478" rpy="0.0 0.0 0.0" />
			<mass value="0.57649" />
			<inertia ixx="0.00051876" ixy="-5.0519e-08" ixz="-5.0469e-06" iyy="0.00039258" iyz="3.4788e-08" izz="0.00029808" />
		</inertial>
		<visual name="motor4310_rev_joint-1.motor4310_in_link_visual">
			<origin xyz="0.0 0.0 0.0" rpy="0.0 0.0 0.0" />
			<geometry>
				<mesh filename="assets/Assem_4310_JOINT/Assem_4310_JOINT/meshes/motor4310_in_link.STL" scale="1.0 1.0 1.0" />
			</geometry>
		</visual>
		<collision name="motor4310_rev_joint-1.motor4310_in_link_collision">
			<origin xyz="0.0 0.0 0.0" rpy="0.0 0.0 0.0" />
			<geometry>
				<mesh filename="assets/Assem_4310_JOINT/Assem_4310_JOINT/meshes/motor4310_in_link.STL" scale="1.0 1.0 1.0" />
			</geometry>
		</collision>
	</link>
	<link name="motor4310_rev_joint-1.motor4310_out_link">
		<inertial>
			<origin xyz="-2.5332e-10 0.0011054 0.013691" rpy="-1.5707963267948966 0.0 0.0" />
			<mass value="0.088545" />
			<inertia ixx="2.4599e-05" ixy="-3.8934e-22" ixz="-1.8263e-21" iyy="3.0632e-05" iyz="7.8406e-07" izz="2.5766e-05" />
		</inertial>
		<visual name="motor4310_rev_joint-1.motor4310_out_link_visual">
			<origin xyz="0.0 0.0 0.0" rpy="-1.5707963267948966 0.0 0.0" />
			<geometry>
				<mesh filename="assets/Assem_4310_JOINT/Assem_4310_JOINT/meshes/motor4310_out_link.STL" scale="1.0 1.0 1.0" />
			</geometry>
		</visual>
		<collision name="motor4310_rev_joint-1.motor4310_out_link_collision">
			<origin xyz="0.0 0.0 0.0" rpy="-1.5707963267948966 0.0 0.0" />
			<geometry>
				<mesh filename="assets/Assem_4310_JOINT/Assem_4310_JOINT/meshes/motor4310_out_link.STL" scale="1.0 1.0 1.0" />
			</geometry>
		</collision>
	</link>
	<link name="r4310to4310-0.15.r4310to4310-0.15">
		<inertial>
			<origin xyz="0.0 0.025 0.0625" rpy="0.0 0.0 0.0" />
			<mass value="9.375000000000002e-05" />
			<inertia ixx="1.7822265625e-07" ixy="0.0" ixz="0.0" iyy="1.7822265625e-07" iyz="0.0" izz="4.882812500000001e-09" />
		</inertial>
		<visual name="r4310to4310-0.15.r4310to4310-0.15_visual">
			<origin xyz="0.0 0.025 0.0625" rpy="0.0 0.0 0.0" />
			<geometry>
				<box size="0.025 0.025 0.15" />
			</geometry>
		</visual>
		<collision name="r4310to4310-0.15.r4310to4310-0.15_collision">
			<origin xyz="0.0 0.025 0.0625" rpy="0.0 0.0 0.0" />
			<geometry>
				<box size="0.025 0.025 0.15" />
			</geometry>
		</collision>
	</link>
	<link name="motor4310_rev_joint-2.motor4310_in_link">
		<inertial>
			<origin xyz="0.0012212 -4.3571e-06 0.035478" rpy="0.0 0.0 0.0" />
			<mass value="0.57649" />
			<inertia ixx="0.00051876" ixy="-5.0519e-08" ixz="-5.0469e-06" iyy="0.00039258" iyz="3.4788e-08" izz="0.00029808" />
		</inertial>
		<visual name="motor4310_rev_joint-2.motor4310_in_link_visual">
			<origin xyz="0.0 0.0 0.0" rpy="0.0 0.0 0.0" />
			<geometry>
				<mesh filename="assets/Assem_4310_JOINT/Assem_4310_JOINT/meshes/motor4310_in_link.STL" scale="1.0 1.0 1.0" />
			</geometry>
		</visual>
		<collision name="motor4310_rev_joint-2.motor4310_in_link_collision">
			<origin xyz="0.0 0.0 0.0" rpy="0.0 0.0 0.0" />
			<geometry>
				<mesh filename="assets/Assem_4310_JOINT/Assem_4310_JOINT/meshes/motor4310_in_link.STL" scale="1.0 1.0 1.0" />
			</geometry>
		</collision>
	</link>
	<link name="motor4310_rev_joint-2.motor4310_out_link">
		<inertial>
			<origin xyz="-2.5332e-10 0.0011054 0.013691" rpy="-1.5707963267948966 0.0 0.0" />
			<mass value="0.088545" />
			<inertia ixx="2.4599e-05" ixy="-3.8934e-22" ixz="-1.8263e-21" iyy="3.0632e-05" iyz="7.8406e-07" izz="2.5766e-05" />
		</inertial>
		<visual name="motor4310_rev_joint-2.motor4310_out_link_visual">
			<origin xyz="0.0 0.0 0.0" rpy="-1.5707963267948966 0.0 0.0" />
			<geometry>
				<mesh filename="assets/Assem_4310_JOINT/Assem_4310_JOINT/meshes/motor4310_out_link.STL" scale="1.0 1.0 1.0" />
			</geometry>
		</visual>
		<collision name="motor4310_rev_joint-2.motor4310_out_link_collision">
			<origin xyz="0.0 0.0 0.0" rpy="-1.5707963267948966 0.0 0.0" />
			<geometry>
				<mesh filename="assets/Assem_4310_JOINT/Assem_4310_JOINT/meshes/motor4310_out_link.STL" scale="1.0 1.0 1.0" />
			</geometry>
		</collision>
	</link>
	<link name="r4310to4310-0.3.r4310to4310-0.3">
		<inertial>
			<origin xyz="0.0 0.025 0.1375" rpy="0.0 0.0 0.0" />
			<mass value="0.00018750000000000003" />
			<inertia ixx="1.4111328124999999e-06" ixy="0.0" ixz="0.0" iyy="1.4111328124999999e-06" iyz="0.0" izz="9.765625000000002e-09" />
		</inertial>
		<visual name="r4310to4310-0.3.r4310to4310-0.3_visual">
			<origin xyz="0.0 0.025 0.1375" rpy="0.0 0.0 0.0" />
			<geometry>
				<box size="0.025 0.025 0.3" />
			</geometry>
		</visual>
		<collision name="r4310to4310-0.3.r4310to4310-0.3_collision">
			<origin xyz="0.0 0.025 0.1375" rpy="0.0 0.0 0.0" />
			<geometry>
				<box size="0.025 0.025 0.3" />
			</geometry>
		</collision>
	</link>
	<link name="motor4310_rev_joint-3.motor4310_in_link">
		<inertial>
			<origin xyz="0.0012212 -4.3571e-06 0.035478" rpy="0.0 0.0 0.0" />
			<mass value="0.57649" />
			<inertia ixx="0.00051876" ixy="-5.0519e-08" ixz="-5.0469e-06" iyy="0.00039258" iyz="3.4788e-08" izz="0.00029808" />
		</inertial>
		<visual name="motor4310_rev_joint-3.motor4310_in_link_visual">
			<origin xyz="0.0 0.0 0.0" rpy="0.0 0.0 0.0" />
			<geometry>
				<mesh filename="assets/Assem_4310_JOINT/Assem_4310_JOINT/meshes/motor4310_in_link.STL" scale="1.0 1.0 1.0" />
			</geometry>
		</visual>
		<collision name="motor4310_rev_joint-3.motor4310_in_link_collision">
			<origin xyz="0.0 0.0 0.0" rpy="0.0 0.0 0.0" />
			<geometry>
				<mesh filename="assets/Assem_4310_JOINT/Assem_4310_JOINT/meshes/motor4310_in_link.STL" scale="1.0 1.0 1.0" />
			</geometry>
		</collision>
	</link>
	<link name="motor4310_rev_joint-3.motor4310_out_link">
		<inertial>
			<origin xyz="-2.5332e-10 0.0011054 0.013691" rpy="-1.5707963267948966 0.0 0.0" />
			<mass value="0.088545" />
			<inertia ixx="2.4599e-05" ixy="-3.8934e-22" ixz="-1.8263e-21" iyy="3.0632e-05" iyz="7.8406e-07" izz="2.5766e-05" />
		</inertial>
		<visual name="motor4310_rev_joint-3.motor4310_out_link_visual">
			<origin xyz="0.0 0.0 0.0" rpy="-1.5707963267948966 0.0 0.0" />
			<geometry>
				<mesh filename="assets/Assem_4310_JOINT/Assem_4310_JOINT/meshes/motor4310_out_link.STL" scale="1.0 1.0 1.0" />
			</geometry>
		</visual>
		<collision name="motor4310_rev_joint-3.motor4310_out_link_collision">
			<origin xyz="0.0 0.0 0.0" rpy="-1.5707963267948966 0.0 0.0" />
			<geometry>
				<mesh filename="assets/Assem_4310_JOINT/Assem_4310_JOINT/meshes/motor4310_out_link.STL" scale="1.0 1.0 1.0" />
			</geometry>
		</collision>
	</link>
	<link name="r4310to4310-0.15-1.r4310to4310-0.15">
		<inertial>
			<origin xyz="0.0 0.025 0.0625" rpy="0.0 0.0 0.0" />
			<mass value="9.375000000000002e-05" />
			<inertia ixx="1.7822265625e-07" ixy="0.0" ixz="0.0" iyy="1.7822265625e-07" iyz="0.0" izz="4.882812500000001e-09" />
		</inertial>
		<visual name="r4310to4310-0.15-1.r4310to4310-0.15_visual">
			<origin xyz="0.0 0.025 0.0625" rpy="0.0 0.0 0.0" />
			<geometry>
				<box size="0.025 0.025 0.15" />
			</geometry>
		</visual>
		<collision name="r4310to4310-0.15-1.r4310to4310-0.15_collision">
			<origin xyz="0.0 0.025 0.0625" rpy="0.0 0.0 0.0" />
			<geometry>
				<box size="0.025 0.025 0.15" />
			</geometry>
		</collision>
	</link>
	<link name="motor4310_rev_joint-4.motor4310_in_link">
		<inertial>
			<origin xyz="0.0012212 -4.3571e-06 0.035478" rpy="0.0 0.0 0.0" />
			<mass value="0.57649" />
			<inertia ixx="0.00051876" ixy="-5.0519e-08" ixz="-5.0469e-06" iyy="0.00039258" iyz="3.4788e-08" izz="0.00029808" />
		</inertial>
		<visual name="motor4310_rev_joint-4.motor4310_in_link_visual">
			<origin xyz="0.0 0.0 0.0" rpy="0.0 0.0 0.0" />
			<geometry>
				<mesh filename="assets/Assem_4310_JOINT/Assem_4310_JOINT/meshes/motor4310_in_link.STL" scale="1.0 1.0 1.0" />
			</geometry>
		</visual>
		<collision name="motor4310_rev_joint-4.motor4310_in_link_collision">
			<origin xyz="0.0 0.0 0.0" rpy="0.0 0.0 0.0" />
			<geometry>
				<mesh filename="assets/Assem_4310_JOINT/Assem_4310_JOINT/meshes/motor4310_in_link.STL" scale="1.0 1.0 1.0" />
			</geometry>
		</collision>
	</link>
	<link name="motor4310_rev_joint-4.motor4310_out_link">
		<inertial>
			<origin xyz="-2.5332e-10 0.0011054 0.013691" rpy="-1.5707963267948966 0.0 0.0" />
			<mass value="0.088545" />
			<inertia ixx="2.4599e-05" ixy="-3.8934e-22" ixz="-1.8263e-21" iyy="3.0632e-05" iyz="7.8406e-07" izz="2.5766e-05" />
		</inertial>
		<visual name="motor4310_rev_joint-4.motor4310_out_link_visual">
			<origin xyz="0.0 0.0 0.0" rpy="-1.5707963267948966 0.0 0.0" />
			<geometry>
				<mesh filename="assets/Assem_4310_JOINT/Assem_4310_JOINT/meshes/motor4310_out_link.STL" scale="1.0 1.0 1.0" />
			</geometry>
		</visual>
		<collision name="motor4310_rev_joint-4.motor4310_out_link_collision">
			<origin xyz="0.0 0.0 0.0" rpy="-1.5707963267948966 0.0 0.0" />
			<geometry>
				<mesh filename="assets/Assem_4310_JOINT/Assem_4310_JOINT/meshes/motor4310_out_link.STL" scale="1.0 1.0 1.0" />
			</geometry>
		</collision>
	</link>
	<link name="r4310to4310-0.15-2.r4310to4310-0.15">
		<inertial>
			<origin xyz="0.0 0.025 0.0625" rpy="0.0 0.0 0.0" />
			<mass value="9.375000000000002e-05" />
			<inertia ixx="1.7822265625e-07" ixy="0.0" ixz="0.0" iyy="1.7822265625e-07" iyz="0.0" izz="4.882812500000001e-09" />
		</inertial>
		<visual name="r4310to4310-0.15-2.r4310to4310-0.15_visual">
			<origin xyz="0.0 0.025 0.0625" rpy="0.0 0.0 0.0" />
			<geometry>
				<box size="0.025 0.025 0.15" />
			</geometry>
		</visual>
		<collision name="r4310to4310-0.15-2.r4310to4310-0.15_collision">
			<origin xyz="0.0 0.025 0.0625" rpy="0.0 0.0 0.0" />
			<geometry>
				<box size="0.025 0.025 0.15" />
			</geometry>
		</collision>
	</link>
	<link name="eef.EEF">
		<inertial>
			<origin xyz="0.0 0.02666666666667 0.04" rpy="3.141592653589793 0.0 0.0" />
			<mass value="0.0" />
			<inertia ixx="0.0" ixy="0.0" ixz="0.0" iyy="0.0" iyz="0.0" izz="0.0" />
		</inertial>
		<visual name="eef.EEF_visual">
			<origin xyz="0.0 0.02666666666667 0.0" rpy="3.141592653589793 0.0 0.0" />
			<geometry>
				<sphere radius="0.02" />
			</geometry>
		</visual>
		<collision name="eef.EEF_collision">
			<origin xyz="0.0 0.02666666666667 0.0" rpy="3.141592653589793 0.0 0.0" />
			<geometry>
				<sphere radius="0.02" />
			</geometry>
		</collision>
	</link>
	<link name="eef.EEF.end-effector.body" />
	<joint name="base_rev_joint.base_rev_joint" type="revolute">
		<origin xyz="-0.0 0.0 0.077" rpy="3.67321858996128e-06 3.6732051003074417e-06 -3.141592653589787" />
		<parent link="base_rev_joint.base_motor_link" />
		<child link="base_rev_joint.base_out_link" />
		<axis xyz="0 0 1" />
		<dynamics damping="0.0" friction="0.0" />
		<limit lower="-3.141592653589793" upper="3.141592653589793" effort="1000.0" velocity="10.0" />
	</joint>
	<joint name="baseto4310-0.15.baseto4310-0.15.2-1" type="fixed">
		<origin xyz="0.0 0.0 0.0" rpy="3.141592653589793 0.0 0.0" />
		<parent link="base_rev_joint.base_out_link" />
		<child link="baseto4310-0.15.baseto4310-0.15" />
	</joint>
	<joint name="motor4310_rev_joint.motor4310_in_link.motor4310_in_linkconnector" type="fixed">
		<origin xyz="0.0 0.0 -0.15" rpy="1.5707963267948966 0.0 0.0" />
		<parent link="baseto4310-0.15.baseto4310-0.15" />
		<child link="motor4310_rev_joint.motor4310_in_link" />
	</joint>
	<joint name="motor4310_rev_joint.motor4310_rev_joint" type="revolute">
		<origin xyz="0.0255 -0.0395 -0.0" rpy="1.5707963267948968 0.0 1.5699999999999987" />
		<parent link="motor4310_rev_joint.motor4310_in_link" />
		<child link="motor4310_rev_joint.motor4310_out_link" />
		<axis xyz="0 0 1" />
		<dynamics damping="0.0" friction="0.0" />
		<limit lower="-3.141592653589793" upper="3.141592653589793" effort="1000.0" velocity="10.0" />
	</joint>
	<joint name="r4310to4310-0.45.r4310to4310-0.45.2-1" type="fixed">
		<origin xyz="0.0 0.0 0.0" rpy="1.5707963267948966 0.0 0.0" />
		<parent link="motor4310_rev_joint.motor4310_out_link" />
		<child link="r4310to4310-0.45.r4310to4310-0.45" />
	</joint>
	<joint name="motor4310_rev_joint-1.motor4310_in_link.motor4310_in_linkconnector" type="fixed">
		<origin xyz="0.0 0.025 0.425" rpy="-1.5707963267948966 0.0 -3.141592653589793" />
		<parent link="r4310to4310-0.45.r4310to4310-0.45" />
		<child link="motor4310_rev_joint-1.motor4310_in_link" />
	</joint>
	<joint name="motor4310_rev_joint-1.motor4310_rev_joint" type="revolute">
		<origin xyz="0.02549999999838 -0.03949999999748 0.0" rpy="1.5707963267948966 0.0 1.56999999997889" />
		<parent link="motor4310_rev_joint-1.motor4310_in_link" />
		<child link="motor4310_rev_joint-1.motor4310_out_link" />
		<axis xyz="0 0 1" />
		<dynamics damping="0.0" friction="0.0" />
		<limit lower="-3.141592653589793" upper="3.141592653589793" effort="1000.0" velocity="10.0" />
	</joint>
	<joint name="r4310to4310-0.15.r4310to4310-0.15.2-1" type="fixed">
		<origin xyz="0.0 0.0 0.0" rpy="1.5707963267948966 0.0 0.0" />
		<parent link="motor4310_rev_joint-1.motor4310_out_link" />
		<child link="r4310to4310-0.15.r4310to4310-0.15" />
	</joint>
	<joint name="motor4310_rev_joint-2.motor4310_in_link.motor4310_in_linkconnector" type="fixed">
		<origin xyz="0.0 0.025 0.125" rpy="-1.5707963267948966 0.0 -3.141592653589793" />
		<parent link="r4310to4310-0.15.r4310to4310-0.15" />
		<child link="motor4310_rev_joint-2.motor4310_in_link" />
	</joint>
	<joint name="motor4310_rev_joint-2.motor4310_rev_joint" type="revolute">
		<origin xyz="0.02549999999838 -0.03949999999748 0.0" rpy="1.5707963267948966 0.0 1.56999999997889" />
		<parent link="motor4310_rev_joint-2.motor4310_in_link" />
		<child link="motor4310_rev_joint-2.motor4310_out_link" />
		<axis xyz="0 0 1" />
		<dynamics damping="0.0" friction="0.0" />
		<limit lower="-3.141592653589793" upper="3.141592653589793" effort="1000.0" velocity="10.0" />
	</joint>
	<joint name="r4310to4310-0.3.r4310to4310-0.3.2-1" type="fixed">
		<origin xyz="0.0 0.0 0.0" rpy="1.5707963267948966 0.0 0.0" />
		<parent link="motor4310_rev_joint-2.motor4310_out_link" />
		<child link="r4310to4310-0.3.r4310to4310-0.3" />
	</joint>
	<joint name="motor4310_rev_joint-3.motor4310_in_link.motor4310_in_linkconnector" type="fixed">
		<origin xyz="0.0 0.025 0.275" rpy="-1.5707963267948966 0.0 -3.141592653589793" />
		<parent link="r4310to4310-0.3.r4310to4310-0.3" />
		<child link="motor4310_rev_joint-3.motor4310_in_link" />
	</joint>
	<joint name="motor4310_rev_joint-3.motor4310_rev_joint" type="revolute">
		<origin xyz="0.02549999999838 -0.03949999999748 0.0" rpy="1.5707963267948966 0.0 1.56999999997889" />
		<parent link="motor4310_rev_joint-3.motor4310_in_link" />
		<child link="motor4310_rev_joint-3.motor4310_out_link" />
		<axis xyz="0 0 1" />
		<dynamics damping="0.0" friction="0.0" />
		<limit lower="-3.141592653589793" upper="3.141592653589793" effort="1000.0" velocity="10.0" />
	</joint>
	<joint name="r4310to4310-0.15-1.r4310to4310-0.15.2-1" type="fixed">
		<origin xyz="0.0 0.0 0.0" rpy="1.5707963267948966 0.0 0.0" />
		<parent link="motor4310_rev_joint-3.motor4310_out_link" />
		<child link="r4310to4310-0.15-1.r4310to4310-0.15" />
	</joint>
	<joint name="motor4310_rev_joint-4.motor4310_in_link.motor4310_in_linkconnector" type="fixed">
		<origin xyz="0.0 0.025 0.125" rpy="-1.5707963267948966 0.0 -3.141592653589793" />
		<parent link="r4310to4310-0.15-1.r4310to4310-0.15" />
		<child link="motor4310_rev_joint-4.motor4310_in_link" />
	</joint>
	<joint name="motor4310_rev_joint-4.motor4310_rev_joint" type="revolute">
		<origin xyz="0.02549999999838 -0.03949999999748 0.0" rpy="1.5707963267948966 0.0 1.56999999997889" />
		<parent link="motor4310_rev_joint-4.motor4310_in_link" />
		<child link="motor4310_rev_joint-4.motor4310_out_link" />
		<axis xyz="0 0 1" />
		<dynamics damping="0.0" friction="0.0" />
		<limit lower="-3.141592653589793" upper="3.141592653589793" effort="1000.0" velocity="10.0" />
	</joint>
	<joint name="r4310to4310-0.15-2.r4310to4310-0.15.2-1" type="fixed">
		<origin xyz="0.0 0.0 0.0" rpy="1.5707963267948966 0.0 0.0" />
		<parent link="motor4310_rev_joint-4.motor4310_out_link" />
		<child link="r4310to4310-0.15-2.r4310to4310-0.15" />
	</joint>
	<joint name="eef.EEF.robot2eef" type="fixed">
		<origin xyz="0.0 0.025 0.125" rpy="-1.5707963267948966 0.0 -3.141592653589793" />
		<parent link="r4310to4310-0.15-2.r4310to4310-0.15" />
		<child link="eef.EEF" />
	</joint>
	<joint name="eef.EEF.end-effector" type="fixed">
		<origin xyz="0.0 0.02666666666667 0.0" rpy="3.141592653589793 0.0 0.0" />
		<parent link="eef.EEF" />
		<child link="eef.EEF.end-effector.body" />
	</joint>
</robot>