<?xml version="1.0" encoding="utf-8"?>
<!-- This URDF was automatically created by SolidWorks to URDF Exporter! Originally created by Stephen Brawner (brawner@gmail.com) 
     Commit Version: 1.6.0-4-g7f85cfe  Build Version: 1.6.7995.38578
     For more information, please see http://wiki.ros.org/sw_urdf_exporter -->
<robot
  name="540_joint.zip">
  <link
    name="base_link">
    <inertial>
      <origin
        xyz="-1.38539547466107E-09 -0.000287119259689533 0.00368996137280351"
        rpy="0 0 0" />
      <mass
        value="0.29029435334" />
      <inertia
        ixx="5.50795565499151E-05"
        ixy="-2.86571926891384E-12"
        ixz="-1.00711791936899E-12"
        iyy="4.53389813728391E-05"
        iyz="5.79699070456781E-07"
        izz="4.02015769123562E-05" />
    </inertial>
    <visual>
      <origin
        xyz="0 0 0"
        rpy="0 0 0" />
      <geometry>
        <mesh
          filename="package://540_joint.zip/meshes/base_link.STL" />
      </geometry>
      <material
        name="">
        <color
          rgba="0.627450980392157 0.627450980392157 0.627450980392157 1" />
      </material>
    </visual>
    <collision>
      <origin
        xyz="0 0 0"
        rpy="0 0 0" />
      <geometry>
        <mesh
          filename="package://540_joint.zip/meshes/base_link.STL" />
      </geometry>
    </collision>
  </link>
  <link
    name="adaptor_link">
    <inertial>
      <origin
        xyz="-0.00133963232913439 -0.0613316332422638 0.0297499714359344"
        rpy="0 0 0" />
      <mass
        value="0.0164593396501985" />
      <inertia
        ixx="6.26759128369106E-06"
        ixy="-2.13191473993262E-07"
        ixz="-5.26404881623548E-12"
        iyy="2.84507172219405E-06"
        iyz="3.47433426545677E-12"
        izz="6.03696612770299E-06" />
    </inertial>
    <visual>
      <origin
        xyz="0 0 0"
        rpy="0 0 0" />
      <geometry>
        <mesh
          filename="package://540_joint.zip/meshes/adaptor_link.STL" />
      </geometry>
      <material
        name="">
        <color
          rgba="0.627450980392157 0.627450980392157 0.627450980392157 1" />
      </material>
    </visual>
    <collision>
      <origin
        xyz="0 0 0"
        rpy="0 0 0" />
      <geometry>
        <mesh
          filename="package://540_joint.zip/meshes/adaptor_link.STL" />
      </geometry>
    </collision>
  </link>
  <joint
    name="adaptor_joint"
    type="continuous">
    <origin
      xyz="0 0 0"
      rpy="0 0 0" />
    <parent
      link="base_link" />
    <child
      link="adaptor_link" />
    <axis
      xyz="0 1 0" />
  </joint>
</robot>