<?xml version="1.0" encoding="utf-8"?>
<!-- This URDF was automatically created by SolidWorks to URDF Exporter! Originally created by Stephen Brawner (brawner@gmail.com) 
     Commit Version: 1.6.0-4-g7f85cfe  Build Version: 1.6.7995.38578
     For more information, please see http://wiki.ros.org/sw_urdf_exporter -->
<robot
  name="540_base">
  <link
    name="base_link">
    <inertial>
      <origin
        xyz="0.000309866219877738 -1.42727209052575E-10 0.017628309391527"
        rpy="0 0 0" />
      <mass
        value="0.182418164745937" />
      <inertia
        ixx="0.000120490016488346"
        ixy="-5.92636030410217E-14"
        ixz="-1.49319277186411E-07"
        iyy="0.000145009530309103"
        iyz="-4.24186454602543E-13"
        izz="0.000228954451007768" />
    </inertial>
    <visual>
      <origin
        xyz="0 0 0"
        rpy="0 0 0" />
      <geometry>
        <mesh
          filename="package://540_base/meshes/base_link.STL" />
      </geometry>
      <material
        name="">
        <color
          rgba="0.627450980392157 0.627450980392157 0.627450980392157 1" />
      </material>
    </visual>
    <collision>
      <origin
        xyz="0 0 0"
        rpy="0 0 0" />
      <geometry>
        <mesh
          filename="package://540_base/meshes/base_link.STL" />
      </geometry>
    </collision>
  </link>
  <link
    name="joint1">
    <inertial>
      <origin
        xyz="-0.0013187 -0.00023587 0.034832"
        rpy="0 0 0" />
      <mass
        value="0.016459" />
      <inertia
        ixx="6.2604E-06"
        ixy="3.9963E-08"
        ixz="2.0986E-07"
        iyy="6.0441E-06"
        iyz="3.7529E-08"
        izz="2.8451E-06" />
    </inertial>
    <visual>
      <origin
        xyz="0 0 0"
        rpy="0 0 0" />
      <geometry>
        <mesh
          filename="package://540_base/meshes/joint1.STL" />
      </geometry>
      <material
        name="">
        <color
          rgba="0.62745 0.62745 0.62745 1" />
      </material>
    </visual>
    <collision>
      <origin
        xyz="0 0 0"
        rpy="0 0 0" />
      <geometry>
        <mesh
          filename="package://540_base/meshes/joint1.STL" />
      </geometry>
    </collision>
  </link>
  <joint
    name="joint1"
    type="continuous">
    <origin
      xyz="0.016 0 0.0575"
      rpy="0 0 -0.17953295" />
    <parent
      link="base_link" />
    <child
      link="joint1" />
    <axis
      xyz="0 0 1" />
  </joint>
</robot>