<?xml version="1.0" encoding="utf-8"?>
<!-- This URDF was automatically created by SolidWorks to URDF Exporter! Originally created by Stephen Brawner (brawner@gmail.com) 
     Commit Version: 1.6.0-4-g7f85cfe  Build Version: 1.6.7995.38578
     For more information, please see http://wiki.ros.org/sw_urdf_exporter -->
<robot
  name="540_base">
  <link
    name="base_link">
    <inertial>
      <origin
        xyz="1.50908492711745E-10 -0.000325418122475302 0.0160772881843097"
        rpy="0 0 0" />
      <mass
        value="0.177193779086753" />
      <inertia
        ixx="0.000127805723719554"
        ixy="-4.15873707549519E-13"
        ixz="6.06391569144552E-14"
        iyy="0.000118748664607956"
        iyz="1.6188350701229E-07"
        izz="0.00019280337926828" />
    </inertial>
    <visual>
      <origin
        xyz="0 0 0"
        rpy="0 0 0" />
      <geometry>
        <mesh
          filename="package://540_base/meshes/base_link.STL" />
      </geometry>
      <material
        name="">
        <color
          rgba="0.627450980392157 0.627450980392157 0.627450980392157 1" />
      </material>
    </visual>
    <collision>
      <origin
        xyz="0 0 0"
        rpy="0 0 0" />
      <geometry>
        <mesh
          filename="package://540_base/meshes/base_link.STL" />
      </geometry>
    </collision>
  </link>
  <link
    name="adaptor_link">
    <inertial>
      <origin
        xyz="-0.0013396323291322 -2.84001572865966E-08 0.021331633242266"
        rpy="0 0 0" />
      <mass
        value="0.0164593396501985" />
      <inertia
        ixx="6.26759128369106E-06"
        ixy="-5.26404884898506E-12"
        ixz="2.13191473993262E-07"
        iyy="6.03696612770299E-06"
        iyz="-3.47433404564492E-12"
        izz="2.84507172219405E-06" />
    </inertial>
    <visual>
      <origin
        xyz="0 0 0"
        rpy="0 0 0" />
      <geometry>
        <mesh
          filename="package://540_base/meshes/adaptor_link.STL" />
      </geometry>
      <material
        name="">
        <color
          rgba="0.627450980392157 0.627450980392157 0.627450980392157 1" />
      </material>
    </visual>
    <collision>
      <origin
        xyz="0 0 0"
        rpy="0 0 0" />
      <geometry>
        <mesh
          filename="package://540_base/meshes/adaptor_link.STL" />
      </geometry>
    </collision>
  </link>
  <joint
    name="adaptor_joint"
    type="continuous">
    <origin
      xyz="0 -0.04 0.0487499998360872"
      rpy="1.5707963267949 0 0" />
    <parent
      link="base_link" />
    <child
      link="adaptor_link" />
    <axis
      xyz="0 0 -1" />
  </joint>
</robot>